Workbook

Sheet metrics
A1: id | B1: Name | C1: AlsoKnownAs | D1: Company | E1: Research | F1: Definition | G1: Data Collection Type | H1: Cardsort Group | I1: Cardsort Group ID | J1: Cardsort Subgroup | K1: Cardsort Subgroup ID | L1: IS_Research | M1: Number of companies | N1: Number of research | O1: value | P1: AI Specific Category | Q1: Outcome Goals | R1: Ease of Collection | S1: Related Metrics
A2: 2 | B2: Adoption Rate | C2: % Adoption of Standards; % Adoption to Golden Standards | D2: 501a; 501b; 501k; 511a; 511b; 511c; 511d; 511e; 511f; 511g; 511h; 511i; 511j; 511k; 511l; 511m; 511n; 511o; 511p | E2: 160; 501; 146; 512 | F2: Relates to engineers’ uptake and sustained use of internal tools, workflows, and platforms, reflecting how effectively these resources integrate into daily workflows and solve critical problems. It serves as a key metric for assessing DevEx success and alignment with productivity goals. | G2: quantitative | H2: Process | I2: =VLOOKUP(H2,cardsort_group_IDs!A:B,2,0) -> 204 | J2: Efficiency | K2: =VLOOKUP(J2,cardsort_subgroup_IDs!A:B,2,0) -> 327 | L2: =IF(E2="-",0,1)+IF(D2="-",0,2) -> 3 | M2: =IF(D2="-",0,LEN(D2)-LEN(SUBSTITUTE(D2,";",""))+1) -> 19 | N2: =IF(E2="-",0,LEN(E2)-LEN(SUBSTITUTE(E2,";",""))+1) -> 4 | O2: =SUM(M2:N2) -> 23 | P2: None | Q2: Developer Experience | R2: Moderate | S2: 140
A3: 4 | B3: Application Startup Duration | C3: - | D3: 201 | E3: - | F3: The time needed to startup an application locally. | G3: quantitative | H3: System | I3: =VLOOKUP(H3,cardsort_group_IDs!A:B,2,0) -> 202 | J3: Build Time | K3: =VLOOKUP(J3,cardsort_subgroup_IDs!A:B,2,0) -> 303 | L3: =IF(E3="-",0,1)+IF(D3="-",0,2) -> 2 | M3: =IF(D3="-",0,LEN(D3)-LEN(SUBSTITUTE(D3,";",""))+1) -> 1 | N3: =IF(E3="-",0,LEN(E3)-LEN(SUBSTITUTE(E3,";",""))+1) -> 0 | O3: =SUM(M3:N3) -> 1 | P3: None | Q3: Developer Experience | R3: Easy | S3: -
A4: 9 | B4: Branch Lifetime | C4: - | D4: 501j; 516c | E4: 501; 183 | F4: The time elapsed between branch creation until merge to main/production. | G4: quantitative | H4: Process | I4: =VLOOKUP(H4,cardsort_group_IDs!A:B,2,0) -> 204 | J4: Cycle Time | K4: =VLOOKUP(J4,cardsort_subgroup_IDs!A:B,2,0) -> 306 | L4: =IF(E4="-",0,1)+IF(D4="-",0,2) -> 3 | M4: =IF(D4="-",0,LEN(D4)-LEN(SUBSTITUTE(D4,";",""))+1) -> 2 | N4: =IF(E4="-",0,LEN(E4)-LEN(SUBSTITUTE(E4,";",""))+1) -> 2 | O4: =SUM(M4:N4) -> 4 | P4: None | Q4: Organizational Effectiveness | R4: Easy | S4: 87
A5: 10 | B5: Burnout Risk Score | C5: - | D5: 501m | E5: 503; 501; 183; 522 | F5: Evaluates developers’ mental health, job fulfillment, and workplace conditions. It serves as a critical indicator of systemic issues that harm productivity and retention. | G5: qualitative | H5: Developer Enablement | I5: =VLOOKUP(H5,cardsort_group_IDs!A:B,2,0) -> 203 | J5: Work Load | K5: =VLOOKUP(J5,cardsort_subgroup_IDs!A:B,2,0) -> 307 | L5: =IF(E5="-",0,1)+IF(D5="-",0,2) -> 3 | M5: =IF(D5="-",0,LEN(D5)-LEN(SUBSTITUTE(D5,";",""))+1) -> 1 | N5: =IF(E5="-",0,LEN(E5)-LEN(SUBSTITUTE(E5,";",""))+1) -> 4 | O5: =SUM(M5:N5) -> 5 | P5: None | Q5: Developer Experience | R5: Moderate | S5: -
A6: 11 | B6: Business Objective Advancement | C6: - | D6: - | E6: 183 | F6: Refers to measuring how effectively software development efforts align with and contribute to achieving specific organizational goals. This metric focuses on outcome-driven impact rather than raw activity metrics (e.g., lines of code, commits). | G6: quantitative | H6: Business | I6: =VLOOKUP(H6,cardsort_group_IDs!A:B,2,0) -> 201 | J6: Optimal Resource Allocation | K6: =VLOOKUP(J6,cardsort_subgroup_IDs!A:B,2,0) -> 302 | L6: =IF(E6="-",0,1)+IF(D6="-",0,2) -> 1 | M6: =IF(D6="-",0,LEN(D6)-LEN(SUBSTITUTE(D6,";",""))+1) -> 0 | N6: =IF(E6="-",0,LEN(E6)-LEN(SUBSTITUTE(E6,";",""))+1) -> 1 | O6: =SUM(M6:N6) -> 1 | P6: None | Q6: Organizational Effectiveness | R6: Complex | S6: -
A7: 12 | B7: Change Failure Rate | C7: Change Fail Rate; Change Fail Percentage | D7: 501c; 131h; 501g; 202a; 511a; 511c; 511d; 511r; 511f; 511g; 511j; 511k; 511m; 511i | E7: 514; 505; 506; 508; 9; 160; 501; 131; 202; 183; 146; 512; 520 | F7: This metric measures the percentage of deployments that cause failures in production, requiring hotfixes or rollbacks. A lower change failure rate indicates a more reliable delivery process. | G7: quantitative | H7: Quality | I7: =VLOOKUP(H7,cardsort_group_IDs!A:B,2,0) -> 205 | J7: Failure Rate | K7: =VLOOKUP(J7,cardsort_subgroup_IDs!A:B,2,0) -> 308 | L7: =IF(E7="-",0,1)+IF(D7="-",0,2) -> 3 | M7: =IF(D7="-",0,LEN(D7)-LEN(SUBSTITUTE(D7,";",""))+1) -> 14 | N7: =IF(E7="-",0,LEN(E7)-LEN(SUBSTITUTE(E7,";",""))+1) -> 13 | O7: =SUM(M7:N7) -> 27 | P7: Impact | Q7: Product Excellence | R7: Easy | S7: 31
A8: 13 | B8: CI Determinism | C8: - | D8: 170 | E8: 521 | F8: The opposite of test flakiness: the chance that a test suite’s result will be valid (not a flake) ensures that identical inputs in a continuous integration (CI) pipeline always produce the same outputs (binaries, artifacts, test results). This guarantees reproducibility, reliability, and traceability in software builds, critical for debugging, compliance, and safety-critical systems. | G8: quantitative | H8: Quality | I8: =VLOOKUP(H8,cardsort_group_IDs!A:B,2,0) -> 205 | J8: Test Coverage | K8: =VLOOKUP(J8,cardsort_subgroup_IDs!A:B,2,0) -> 309 | L8: =IF(E8="-",0,1)+IF(D8="-",0,2) -> 3 | M8: =IF(D8="-",0,LEN(D8)-LEN(SUBSTITUTE(D8,";",""))+1) -> 1 | N8: =IF(E8="-",0,LEN(E8)-LEN(SUBSTITUTE(E8,";",""))+1) -> 1 | O8: =SUM(M8:N8) -> 2 | P8: None | Q8: Product Excellence | R8: Moderate | S8: -
A9: 14 | B9: CI Pipeline Failure Rate | C9: - | D9: 501g; 510 | E9: 501; 521 | F9: Measures the percentage of builds or automated workflows in a continuous integration (CI) system that fail due to errors (e.g., compilation issues, test failures, dependency conflicts). | G9: quantitative | H9: Quality | I9: =VLOOKUP(H9,cardsort_group_IDs!A:B,2,0) -> 205 | J9: Failure Rate | K9: =VLOOKUP(J9,cardsort_subgroup_IDs!A:B,2,0) -> 308 | L9: =IF(E9="-",0,1)+IF(D9="-",0,2) -> 3 | M9: =IF(D9="-",0,LEN(D9)-LEN(SUBSTITUTE(D9,";",""))+1) -> 2 | N9: =IF(E9="-",0,LEN(E9)-LEN(SUBSTITUTE(E9,";",""))+1) -> 2 | O9: =SUM(M9:N9) -> 4 | P9: None | Q9: Product Excellence | R9: Easy | S9: -
A10: 15 | B10: CI Build Time | C10: Post-Commit CI Speed; CI Pipeline P50 Build Time | D10: 501g; 170; 501o | E10: 501; 521 | F10: Refers to the (median or mean) duration of successful builds in a continuous integration (CI) pipeline. Might be quantified for individual or a group of commits. | G10: quantitative | H10: Process | I10: =VLOOKUP(H10,cardsort_group_IDs!A:B,2,0) -> 204 | J10: Cycle Time | K10: =VLOOKUP(J10,cardsort_subgroup_IDs!A:B,2,0) -> 306 | L10: =IF(E10="-",0,1)+IF(D10="-",0,2) -> 3 | M10: =IF(D10="-",0,LEN(D10)-LEN(SUBSTITUTE(D10,";",""))+1) -> 3 | N10: =IF(E10="-",0,LEN(E10)-LEN(SUBSTITUTE(E10,";",""))+1) -> 2 | O10: =SUM(M10:N10) -> 5 | P10: None | Q10: Developer Experience | R10: Easy | S10: -
A11: 16 | B11: Code Churn | C11: - | D11: 501m; 131e | E11: 105; 501; 131 | F11: Is the amount of code rewritten shortly after being written. | G11: quantitative | H11: Quality | I11: =VLOOKUP(H11,cardsort_group_IDs!A:B,2,0) -> 205 | J11: Code Rework | K11: =VLOOKUP(J11,cardsort_subgroup_IDs!A:B,2,0) -> 310 | L11: =IF(E11="-",0,1)+IF(D11="-",0,2) -> 3 | M11: =IF(D11="-",0,LEN(D11)-LEN(SUBSTITUTE(D11,";",""))+1) -> 2 | N11: =IF(E11="-",0,LEN(E11)-LEN(SUBSTITUTE(E11,";",""))+1) -> 3 | O11: =SUM(M11:N11) -> 5 | P11: None | Q11: Product Excellence | R11: Easy | S11: -
A12: 17 | B12: Code Reviewer Response Time | C12: Code Reviewer Response Time (P50 and P90); Diff Response Time | D12: 170; 146b; 131l; 517a; 516c | E12: 506; 131; 146; 183; 146; 521 | F12: Measures how long it takes, in business hours, for code reviewers to respond to each update of the code review from the author. | G12: quantitative | H12: Team | I12: =VLOOKUP(H12,cardsort_group_IDs!A:B,2,0) -> 206 | J12: Review Process | K12: =VLOOKUP(J12,cardsort_subgroup_IDs!A:B,2,0) -> 311 | L12: =IF(E12="-",0,1)+IF(D12="-",0,2) -> 3 | M12: =IF(D12="-",0,LEN(D12)-LEN(SUBSTITUTE(D12,";",""))+1) -> 5 | N12: =IF(E12="-",0,LEN(E12)-LEN(SUBSTITUTE(E12,";",""))+1) -> 6 | O12: =SUM(M12:N12) -> 11 | P12: None | Q12: Organizational Effectiveness | R12: Easy | S12: -
A13: 18 | B13: Code Rework Rate | C13: PR revert rate | D13: 131q; 131r; 511k | E13: 131; 520 | F13: Is the percentage of code changes that modify recently changed code. | G13: quantitative | H13: Quality | I13: =VLOOKUP(H13,cardsort_group_IDs!A:B,2,0) -> 205 | J13: Code Rework | K13: =VLOOKUP(J13,cardsort_subgroup_IDs!A:B,2,0) -> 310 | L13: =IF(E13="-",0,1)+IF(D13="-",0,2) -> 3 | M13: =IF(D13="-",0,LEN(D13)-LEN(SUBSTITUTE(D13,";",""))+1) -> 3 | N13: =IF(E13="-",0,LEN(E13)-LEN(SUBSTITUTE(E13,";",""))+1) -> 2 | O13: =SUM(M13:N13) -> 5 | P13: Impact | Q13: Product Excellence | R13: Easy | S13: -
A14: 19 | B14: Produced Code | C14: KLOC - Lines of Code; Code Owned by Time; Committed Source Lines of Code by Time; Source Lines of Code by Time; Lines Deleted; Lines Inserted; Number of Lines of Code Modified; Engineering Productivity; Commit Count | D14: 501m; 32a; 232a; 511b; 232 | E14: 503; 7; 13; 15; 31; 36; 46; 47; 49; 51; 52; 92; 101; 111; 233; 237; 20; 32; 501; 131 | F14: Tracks contributions to the codebase, for example by number of lines of code. | G14: quantitative | H14: Output | I14: =VLOOKUP(H14,cardsort_group_IDs!A:B,2,0) -> 207 | J14: Produced Output | K14: =VLOOKUP(J14,cardsort_subgroup_IDs!A:B,2,0) -> 312 | L14: =IF(E14="-",0,1)+IF(D14="-",0,2) -> 3 | M14: =IF(D14="-",0,LEN(D14)-LEN(SUBSTITUTE(D14,";",""))+1) -> 5 | N14: =IF(E14="-",0,LEN(E14)-LEN(SUBSTITUTE(E14,";",""))+1) -> 20 | O14: =SUM(M14:N14) -> 25 | P14: None | Q14: Organizational Effectiveness | R14: Easy | S14: -
A15: 20 | B15: Cognitive Load Score | C15: Cognitive Effort | D15: - | E15: 504; 11; 96; 214; 513; 517b; 523 | F15: Self-reported mental effort required to perform tasks. Avoiding multitasking, high WIP (work in progress) counts, and attention splitting to maintain focus and reduce cognitive overhead. | G15: qualitative | H15: Developer Enablement | I15: =VLOOKUP(H15,cardsort_group_IDs!A:B,2,0) -> 203 | J15: Ease of Delivery | K15: =VLOOKUP(J15,cardsort_subgroup_IDs!A:B,2,0) -> 313 | L15: =IF(E15="-",0,1)+IF(D15="-",0,2) -> 1 | M15: =IF(D15="-",0,LEN(D15)-LEN(SUBSTITUTE(D15,";",""))+1) -> 0 | N15: =IF(E15="-",0,LEN(E15)-LEN(SUBSTITUTE(E15,";",""))+1) -> 7 | O15: =SUM(M15:N15) -> 7 | P15: Impact | Q15: Developer Experience | R15: Complex | S15: -
A16: 22 | B16: CI/CD Health Score | C16: - | D16: 501m | E16: 503; 501 | F16: Measures the effectiveness of automated build, test, and deployment processes in enabling rapid, reliable software delivery. | G16: quantitative | H16: Process | I16: =VLOOKUP(H16,cardsort_group_IDs!A:B,2,0) -> 204 | J16: Efficiency | K16: =VLOOKUP(J16,cardsort_subgroup_IDs!A:B,2,0) -> 327 | L16: =IF(E16="-",0,1)+IF(D16="-",0,2) -> 3 | M16: =IF(D16="-",0,LEN(D16)-LEN(SUBSTITUTE(D16,";",""))+1) -> 1 | N16: =IF(E16="-",0,LEN(E16)-LEN(SUBSTITUTE(E16,";",""))+1) -> 2 | O16: =SUM(M16:N16) -> 3 | P16: None | Q16: Organizational Effectiveness | R16: Moderate | S16: -
A17: 23 | B17: Contribution Volume | C17: Number of Modifications / Modules / WorkItems / Requirements | D17: - | E17: 506; 15 | F17: The number of contribution units, such as modifications, modules touched, work items closed, or requirements implemented, by an individual developer or team within a period. Used to spot trends in team capacity, not as a standalone productivity score. | G17: quantitative | H17: Team | I17: =VLOOKUP(H17,cardsort_group_IDs!A:B,2,0) -> 206 | J17: Task Assignment | K17: =VLOOKUP(J17,cardsort_subgroup_IDs!A:B,2,0) -> 316 | L17: =IF(E17="-",0,1)+IF(D17="-",0,2) -> 1 | M17: =IF(D17="-",0,LEN(D17)-LEN(SUBSTITUTE(D17,";",""))+1) -> 0 | N17: =IF(E17="-",0,LEN(E17)-LEN(SUBSTITUTE(E17,";",""))+1) -> 2 | O17: =SUM(M17:N17) -> 2 | P17: None | Q17: Organizational Effectiveness | R17: Moderate | S17: 134
A18: 24 | B18: Cost Savings | C18: - | D18: - | E18: 508 | F18: Relates to strategic reductions in product development and operational expenses achieved through optimized engineering practices, aligning technical efficiency with business profitability. This is measured by tracking how engineering improvements directly lower costs while maintaining quality and delivery speed. | G18: quantitative | H18: Business | I18: =VLOOKUP(H18,cardsort_group_IDs!A:B,2,0) -> 201 | J18: Optimal Resource Allocation | K18: =VLOOKUP(J18,cardsort_subgroup_IDs!A:B,2,0) -> 302 | L18: =IF(E18="-",0,1)+IF(D18="-",0,2) -> 1 | M18: =IF(D18="-",0,LEN(D18)-LEN(SUBSTITUTE(D18,";",""))+1) -> 0 | N18: =IF(E18="-",0,LEN(E18)-LEN(SUBSTITUTE(E18,";",""))+1) -> 1 | O18: =SUM(M18:N18) -> 1 | P18: None | Q18: Organizational Effectiveness | R18: Complex | S18: -
A19: 25 | B19: Customer Satisfaction Score | C19: CSAT; Customer Experience; Customer Satisfaction; Customer Satisfaction Scores; User/customer satisfaction; NPS | D19: - | E19: 506; 508; 183 | F19: Measures how pleased customers are with a product, service, or interaction, typically via surveys. Responses are aggregated into a percentage score representing the proportion of satisfied customers | G19: qualitative | H19: Customer | I19: =VLOOKUP(H19,cardsort_group_IDs!A:B,2,0) -> 208 | J19: Product Quality | K19: =VLOOKUP(J19,cardsort_subgroup_IDs!A:B,2,0) -> 317 | L19: =IF(E19="-",0,1)+IF(D19="-",0,2) -> 1 | M19: =IF(D19="-",0,LEN(D19)-LEN(SUBSTITUTE(D19,";",""))+1) -> 0 | N19: =IF(E19="-",0,LEN(E19)-LEN(SUBSTITUTE(E19,";",""))+1) -> 3 | O19: =SUM(M19:N19) -> 3 | P19: None | Q19: Product Excellence | R19: Moderate | S19: -
A20: 26 | B20: Number of Customer-Reported Defects | C20: - | D20: 131m; 131n | E20: 131 | F20: Bugs reported by customers in production. | G20: quantitative | H20: Customer | I20: =VLOOKUP(H20,cardsort_group_IDs!A:B,2,0) -> 208 | J20: Product Quality | K20: =VLOOKUP(J20,cardsort_subgroup_IDs!A:B,2,0) -> 317 | L20: =IF(E20="-",0,1)+IF(D20="-",0,2) -> 3 | M20: =IF(D20="-",0,LEN(D20)-LEN(SUBSTITUTE(D20,";",""))+1) -> 2 | N20: =IF(E20="-",0,LEN(E20)-LEN(SUBSTITUTE(E20,";",""))+1) -> 1 | O20: =SUM(M20:N20) -> 3 | P20: None | Q20: Product Excellence | R20: Easy | S20: 80; 29; 42; 133
A21: 27 | B21: Cycle Time | C21: Time From Creating a Patch to Patch Release; Time to Value; Time to Merge (TTM); PR Cycle Time | D21: 501m; 131i; 501d; 209; 510; 511b; 511r; 511m; 511h; 511q; 511p; 517a; 516c | E21: 9; 235; 241; 501; 131; 520 | F21: Measures the time from code commit to code running in production. Shows how quickly team can respond to business needs. | G21: quantitative | H21: Process | I21: =VLOOKUP(H21,cardsort_group_IDs!A:B,2,0) -> 204 | J21: Cycle Time | K21: =VLOOKUP(J21,cardsort_subgroup_IDs!A:B,2,0) -> 306 | L21: =IF(E21="-",0,1)+IF(D21="-",0,2) -> 3 | M21: =IF(D21="-",0,LEN(D21)-LEN(SUBSTITUTE(D21,";",""))+1) -> 13 | N21: =IF(E21="-",0,LEN(E21)-LEN(SUBSTITUTE(E21,";",""))+1) -> 6 | O21: =SUM(M21:N21) -> 19 | P21: Impact | Q21: Organizational Effectiveness | R21: Easy | S21: -
A22: 29 | B22: Number of Defects | C22: Defects per Function Point; Defect Density; Weighted Defects | D22: - | E22: 236; 520; 92 | F22: Measures defect density: the number of errors or failures normalized by a size unit (e.g., function points), sometimes severity-weighted, indicating codebase quality independent of project size. | G22: quantitative | H22: Quality | I22: =VLOOKUP(H22,cardsort_group_IDs!A:B,2,0) -> 205 | J22: Failure Rate | K22: =VLOOKUP(J22,cardsort_subgroup_IDs!A:B,2,0) -> 308 | L22: =IF(E22="-",0,1)+IF(D22="-",0,2) -> 1 | M22: =IF(D22="-",0,LEN(D22)-LEN(SUBSTITUTE(D22,";",""))+1) -> 0 | N22: =IF(E22="-",0,LEN(E22)-LEN(SUBSTITUTE(E22,";",""))+1) -> 3 | O22: =SUM(M22:N22) -> 3 | P22: None | Q22: Product Excellence | R22: Easy | S22: -
A23: 30 | B23: Deployment Frequency | C23: - | D23: 146b; 131k; 131b; 202a; 501k; 146a; 209; 511i; 511d | E23: 505; 506; 514; 508; 9; 96; 160; 501; 131; 202; 146; 182 | F23: How often an organization deploys code/builds to a production environment, regardless of whether that change is yet visible to end users. Higher deployment frequency indicates a more agile and responsive delivery process. | G23: quantitative | H23: Customer | I23: =VLOOKUP(H23,cardsort_group_IDs!A:B,2,0) -> 208 | J23: Deployment Frequency | K23: =VLOOKUP(J23,cardsort_subgroup_IDs!A:B,2,0) -> 318 | L23: =IF(E23="-",0,1)+IF(D23="-",0,2) -> 3 | M23: =IF(D23="-",0,LEN(D23)-LEN(SUBSTITUTE(D23,";",""))+1) -> 9 | N23: =IF(E23="-",0,LEN(E23)-LEN(SUBSTITUTE(E23,";",""))+1) -> 12 | O23: =SUM(M23:N23) -> 21 | P23: Impact | Q23: Organizational Effectiveness | R23: Easy | S23: 94; 79
A24: 31 | B24: Deployment Success Rate | C24: Build Success Rate | D24: 170 | E24: 9; 57; 183; 521 | F24: The percentage of deployment (CI/CD) runs that complete successfully. | G24: quantitative | H24: Quality | I24: =VLOOKUP(H24,cardsort_group_IDs!A:B,2,0) -> 205 | J24: Code Quality | K24: =VLOOKUP(J24,cardsort_subgroup_IDs!A:B,2,0) -> 319 | L24: =IF(E24="-",0,1)+IF(D24="-",0,2) -> 3 | M24: =IF(D24="-",0,LEN(D24)-LEN(SUBSTITUTE(D24,";",""))+1) -> 1 | N24: =IF(E24="-",0,LEN(E24)-LEN(SUBSTITUTE(E24,";",""))+1) -> 4 | O24: =SUM(M24:N24) -> 5 | P24: None | Q24: Organizational Effectiveness | R24: Easy | S24: 12
A25: 32 | B25: Number of Deploys per Service | C25: - | D25: 501c | E25: 501 | F25: This metric in software engineering measures how often a specific service or microservice is deployed within a given timeframe. This metric is commonly used in DevOps and microservices architectures to track deployment frequency across different services. | G25: quantitative | H25: Customer | I25: =VLOOKUP(H25,cardsort_group_IDs!A:B,2,0) -> 208 | J25: Deployment Frequency | K25: =VLOOKUP(J25,cardsort_subgroup_IDs!A:B,2,0) -> 318 | L25: =IF(E25="-",0,1)+IF(D25="-",0,2) -> 3 | M25: =IF(D25="-",0,LEN(D25)-LEN(SUBSTITUTE(D25,";",""))+1) -> 1 | N25: =IF(E25="-",0,LEN(E25)-LEN(SUBSTITUTE(E25,";",""))+1) -> 1 | O25: =SUM(M25:N25) -> 2 | P25: None | Q25: Organizational Effectiveness | R25: Easy | S25: -
A26: 33 | B26: Design | C26: - | D26: 501m | E26: 503; 501 | F26: Captures documentation quality, architectural decisions, and prototyping efforts. | G26: qualitative | H26: Process | I26: =VLOOKUP(H26,cardsort_group_IDs!A:B,2,0) -> 204 | J26: Self-Service and Documentation | K26: =VLOOKUP(J26,cardsort_subgroup_IDs!A:B,2,0) -> 320 | L26: =IF(E26="-",0,1)+IF(D26="-",0,2) -> 3 | M26: =IF(D26="-",0,LEN(D26)-LEN(SUBSTITUTE(D26,";",""))+1) -> 1 | N26: =IF(E26="-",0,LEN(E26)-LEN(SUBSTITUTE(E26,";",""))+1) -> 2 | O26: =SUM(M26:N26) -> 3 | P26: None | Q26: Product Excellence | R26: Complex | S26: -
A27: 34 | B27: Local Build Time | C27: Developer Build Time; Build Time; Application/Package Build Duration; Build Time Efficiency | D27: 170; 131c; 131o; 201 | E27: 503; 501 | F27: Measures the time, in seconds, developers spend waiting for their builds to finish locally during development. Impacts developer flow and productivity. Considered e.g. as median (P50) or P90. | G27: quantitative | H27: System | I27: =VLOOKUP(H27,cardsort_group_IDs!A:B,2,0) -> 202 | J27: Build Time | K27: =VLOOKUP(J27,cardsort_subgroup_IDs!A:B,2,0) -> 303 | L27: =IF(E27="-",0,1)+IF(D27="-",0,2) -> 3 | M27: =IF(D27="-",0,LEN(D27)-LEN(SUBSTITUTE(D27,";",""))+1) -> 4 | N27: =IF(E27="-",0,LEN(E27)-LEN(SUBSTITUTE(E27,";",""))+1) -> 2 | O27: =SUM(M27:N27) -> 6 | P27: None | Q27: Developer Experience | R27: Easy | S27: -
A28: 36 | B28: Developer Satisfaction | C28: CSAT; DSAT; NSAT; Satisfaction Score; Developer Sentiment; Developer Satisfaction; Employee satisfaction; Net User Satisfaction; Satisfaction with Engineering System; Platform and Tool Satisfaction; AI tool CSAT | D28: 501l; 501a; 202a; 501m; 501i; 501f; 501h; 170; 501d; 6a; 510; 511a; 511b; 511d; 511f; 511j; 511k; 511l; 511n; 511q; 511c; 511e; 511g; 511h; 511m; 511n; 511r | E28: 514; 506; 503; 43; 96; 202; 235; 5; 6; 160; 501; 131; 183; 146; 512; 520; 522; 523 | F28: Customer satisfaction score for developers. Measures developer and team happiness with regards to development systems. | G28: qualitative | H28: Developer Enablement | I28: =VLOOKUP(H28,cardsort_group_IDs!A:B,2,0) -> 203 | J28: Satisfaction | K28: =VLOOKUP(J28,cardsort_subgroup_IDs!A:B,2,0) -> 322 | L28: =IF(E28="-",0,1)+IF(D28="-",0,2) -> 3 | M28: =IF(D28="-",0,LEN(D28)-LEN(SUBSTITUTE(D28,";",""))+1) -> 27 | N28: =IF(E28="-",0,LEN(E28)-LEN(SUBSTITUTE(E28,";",""))+1) -> 18 | O28: =SUM(M28:N28) -> 45 | P28: Impact | Q28: Developer Experience | R28: Easy | S28: 155; 162
A29: 37 | B29: Velocity Index Benchmark | C29: - | D29: - | E29: 506 | F29: The Developer Velocity Index (DVI) is a survey that measures an enterprise’s technology, working practices, and organizational enablement and benchmarks them against peers. This comparison helps unearth specific areas of opportunity, whether in backlog management, testing, or security and compliance. For example, one company, well known for its technological progress and all-star developers, sought to define standard working practices more thoughtfully for cross-team collaboration after discovering a high amount of dissatisfaction, rework, and inefficiency reported by developers. | G29: qualitative | H29: Business | I29: =VLOOKUP(H29,cardsort_group_IDs!A:B,2,0) -> 201 | J29: Optimal Resource Allocation | K29: =VLOOKUP(J29,cardsort_subgroup_IDs!A:B,2,0) -> 302 | L29: =IF(E29="-",0,1)+IF(D29="-",0,2) -> 1 | M29: =IF(D29="-",0,LEN(D29)-LEN(SUBSTITUTE(D29,";",""))+1) -> 0 | N29: =IF(E29="-",0,LEN(E29)-LEN(SUBSTITUTE(E29,";",""))+1) -> 1 | O29: =SUM(M29:N29) -> 1 | P29: None | Q29: Organizational Effectiveness | R29: Complex | S29: -
A30: 38 | B30: Diff Authoring Time | C30: Diff Authoring Time (DAT); PR Authoring Time; Diffs per Engineer (PRs or MRs); Commits Performed by Time; Time Spent per Task; Implementation Time per User Story; Task Completion Time; Coding Time; Time to Commit per LOC Changed | D30: 131l; 32a; 511b; 511h | E30: 514; 7; 14; 31; 49; 52; 57; 96;108; 192; 234; 32; 131 | F30: Aims to capture all active human developer time spent on a particular diff, split by the different roles involved. This information is made available in a privacy-aware manner. Active human work on a computer tends to be highly sequential, even if such individual sequences can be extremely short. | G30: quantitative | H30: Process | I30: =VLOOKUP(H30,cardsort_group_IDs!A:B,2,0) -> 204 | J30: Cycle Time | K30: =VLOOKUP(J30,cardsort_subgroup_IDs!A:B,2,0) -> 306 | L30: =IF(E30="-",0,1)+IF(D30="-",0,2) -> 3 | M30: =IF(D30="-",0,LEN(D30)-LEN(SUBSTITUTE(D30,";",""))+1) -> 4 | N30: =IF(E30="-",0,LEN(E30)-LEN(SUBSTITUTE(E30,";",""))+1) -> 13 | O30: =SUM(M30:N30) -> 17 | P30: Impact | Q30: Developer Experience | R30: Moderate | S30: -
A31: 39 | B31: Discoverability of Documentation and Expertise | C31: - | D31: 501m | E31: 503; 501 | F31: Refers to how easily developers can locate critical information (e.g., codebase guides, API references) or identify colleagues with specific knowledge. | G31: qualitative | H31: Process | I31: =VLOOKUP(H31,cardsort_group_IDs!A:B,2,0) -> 204 | J31: Self-Service and Documentation | K31: =VLOOKUP(J31,cardsort_subgroup_IDs!A:B,2,0) -> 320 | L31: =IF(E31="-",0,1)+IF(D31="-",0,2) -> 3 | M31: =IF(D31="-",0,LEN(D31)-LEN(SUBSTITUTE(D31,";",""))+1) -> 1 | N31: =IF(E31="-",0,LEN(E31)-LEN(SUBSTITUTE(E31,";",""))+1) -> 2 | O31: =SUM(M31:N31) -> 3 | P31: None | Q31: Developer Experience | R31: Moderate | S31: -
A32: 40 | B32: Ease of Delivery | C32: Ease | D32: 501c; 501l; 501b; 501e; 501g; 501d; 5a | E32: 514; 5; 160; 501; 115; 146; 183; 522 | F32: Refers to how simple, straightforward, and frictionless it is for developers or teams to deliver software, features, or updates through their development processes and tooling. Captures the perceived and actual effort required to move work from development to production. | G32: qualitative | H32: Developer Enablement | I32: =VLOOKUP(H32,cardsort_group_IDs!A:B,2,0) -> 203 | J32: Ease of Delivery | K32: =VLOOKUP(J32,cardsort_subgroup_IDs!A:B,2,0) -> 313 | L32: =IF(E32="-",0,1)+IF(D32="-",0,2) -> 3 | M32: =IF(D32="-",0,LEN(D32)-LEN(SUBSTITUTE(D32,";",""))+1) -> 7 | N32: =IF(E32="-",0,LEN(E32)-LEN(SUBSTITUTE(E32,";",""))+1) -> 8 | O32: =SUM(M32:N32) -> 15 | P32: Impact | Q32: Developer Experience | R32: Moderate | S32: -
A33: 41 | B33: Engineer Engagement | C33: Engagement; Developer Engagement | D33: 501b; 501c; 501e; 501d | E33: 160; 501 | F33: Refers to the emotional commitment, motivation, and involvement that software engineers or developers have toward their work, team, and organization. | G33: qualitative | H33: Developer Enablement | I33: =VLOOKUP(H33,cardsort_group_IDs!A:B,2,0) -> 203 | J33: Impact and Efficacy | K33: =VLOOKUP(J33,cardsort_subgroup_IDs!A:B,2,0) -> 321 | L33: =IF(E33="-",0,1)+IF(D33="-",0,2) -> 3 | M33: =IF(D33="-",0,LEN(D33)-LEN(SUBSTITUTE(D33,";",""))+1) -> 4 | N33: =IF(E33="-",0,LEN(E33)-LEN(SUBSTITUTE(E33,";",""))+1) -> 2 | O33: =SUM(M33:N33) -> 6 | P33: None | Q33: Developer Experience | R33: Moderate | S33: -
A34: 42 | B34: Error Rates | C34: Defect Rate | D34: - | E34: 508; 9; 101 | F34: Quantifies the frequency of user or system mistakes during interactions with a product (e.g., failed API requests, UI slips, or task errors) | G34: quantitative | H34: Quality | I34: =VLOOKUP(H34,cardsort_group_IDs!A:B,2,0) -> 205 | J34: Failure Rate | K34: =VLOOKUP(J34,cardsort_subgroup_IDs!A:B,2,0) -> 308 | L34: =IF(E34="-",0,1)+IF(D34="-",0,2) -> 1 | M34: =IF(D34="-",0,LEN(D34)-LEN(SUBSTITUTE(D34,";",""))+1) -> 0 | N34: =IF(E34="-",0,LEN(E34)-LEN(SUBSTITUTE(E34,";",""))+1) -> 3 | O34: =SUM(M34:N34) -> 3 | P34: None | Q34: Product Excellence | R34: Easy | S34: 26; 29; 70; 133
A35: 43 | B35: Experience of New Members | C35: - | D35: 501m | E35: 503; 501 | F35: Is a combination of satisfaction, well-being and integration indicators to ensure new developers feel supported, included and able to contribute effectively. | G35: qualitative | H35: Developer Enablement | I35: =VLOOKUP(H35,cardsort_group_IDs!A:B,2,0) -> 203 | J35: Onboarding | K35: =VLOOKUP(J35,cardsort_subgroup_IDs!A:B,2,0) -> 323 | L35: =IF(E35="-",0,1)+IF(D35="-",0,2) -> 3 | M35: =IF(D35="-",0,LEN(D35)-LEN(SUBSTITUTE(D35,";",""))+1) -> 1 | N35: =IF(E35="-",0,LEN(E35)-LEN(SUBSTITUTE(E35,";",""))+1) -> 2 | O35: =SUM(M35:N35) -> 3 | P35: None | Q35: Developer Experience | R35: Moderate | S35: -
A36: 44 | B36: Experiment Velocity | C36: A/B Test Throughput | D36: 501i; 511i | E36: 501; 146 | F36: Refers to the speed and efficiency at which the platform conducts and evaluates A/B tests to optimize features, algorithms, and user experiences. | G36: quantitative | H36: System | I36: =VLOOKUP(H36,cardsort_group_IDs!A:B,2,0) -> 202 | J36: Performance | K36: =VLOOKUP(J36,cardsort_subgroup_IDs!A:B,2,0) -> 324 | L36: =IF(E36="-",0,1)+IF(D36="-",0,2) -> 3 | M36: =IF(D36="-",0,LEN(D36)-LEN(SUBSTITUTE(D36,";",""))+1) -> 2 | N36: =IF(E36="-",0,LEN(E36)-LEN(SUBSTITUTE(E36,";",""))+1) -> 2 | O36: =SUM(M36:N36) -> 4 | P36: Impact | Q36: Organizational Effectiveness | R36: Moderate | S36: -
A37: 45 | B37: Failed Deployment Recovery Time | C37: - | D37: - | E37: 514; 505 | F37: This metric measures the time it takes to recover from a failed deployment (e.g. outage or service failure in production). A lower recovery time indicates a more resilient and responsive system. | G37: quantitative | H37: System | I37: =VLOOKUP(H37,cardsort_group_IDs!A:B,2,0) -> 202 | J37: Failure Recovery | K37: =VLOOKUP(J37,cardsort_subgroup_IDs!A:B,2,0) -> 325 | L37: =IF(E37="-",0,1)+IF(D37="-",0,2) -> 1 | M37: =IF(D37="-",0,LEN(D37)-LEN(SUBSTITUTE(D37,";",""))+1) -> 0 | N37: =IF(E37="-",0,LEN(E37)-LEN(SUBSTITUTE(E37,";",""))+1) -> 2 | O37: =SUM(M37:N37) -> 2 | P37: None | Q37: Organizational Effectiveness | R37: Easy | S37: -
A38: 46 | B38: Feedback Latency | C38: Time to Feedback; CI Feedback Time | D38: - | E38: 504; 214 | F38: The average time between a developer action (e.g., code push, PR submission, build trigger) and the developer receiving a response (e.g., CI/test results, build status, review comments). | G38: quantitative | H38: Team | I38: =VLOOKUP(H38,cardsort_group_IDs!A:B,2,0) -> 206 | J38: Collaboration | K38: =VLOOKUP(J38,cardsort_subgroup_IDs!A:B,2,0) -> 326 | L38: =IF(E38="-",0,1)+IF(D38="-",0,2) -> 1 | M38: =IF(D38="-",0,LEN(D38)-LEN(SUBSTITUTE(D38,";",""))+1) -> 0 | N38: =IF(E38="-",0,LEN(E38)-LEN(SUBSTITUTE(E38,";",""))+1) -> 2 | O38: =SUM(M38:N38) -> 2 | P38: Impact | Q38: Developer Experience | R38: Moderate | S38: -
A39: 50 | B39: Focus Time | C39: Flow State; Deep Work; Focused Work; Uninterrupted Time | D39: 501n; 501j; 501b; 203; 6a; 501m; 517a | E39: 504; 214; 6; 501; 183; 503 | F39: The ability to work in focus or flow, i.e. uninterrupted, in meeting-free blocks that allow the developer to concentrate deeply on their work. Often reported as percentage of total time or average time. | G39: both | H39: Developer Enablement | I39: =VLOOKUP(H39,cardsort_group_IDs!A:B,2,0) -> 203 | J39: Focus Work | K39: =VLOOKUP(J39,cardsort_subgroup_IDs!A:B,2,0) -> 305 | L39: =IF(E39="-",0,1)+IF(D39="-",0,2) -> 3 | M39: =IF(D39="-",0,LEN(D39)-LEN(SUBSTITUTE(D39,";",""))+1) -> 7 | N39: =IF(E39="-",0,LEN(E39)-LEN(SUBSTITUTE(E39,";",""))+1) -> 6 | O39: =SUM(M39:N39) -> 13 | P39: None | Q39: Developer Experience | R39: Complex | S39: 59; 157
A40: 56 | B40: Impact | C40: Direct Customer Impact Measures | D40: 501m | E40: 503; 501; 183 | F40: Evaluates the tangible outcomes and value delivered by development efforts. Unlike raw outputs (e.g., lines of code), impact focuses on business results and user-centric effects of software work. Making significant contributions to one’s business unit or area of ownership, ensuring that work has a tangible impact. | G40: quantitative | H40: Developer Enablement | I40: =VLOOKUP(H40,cardsort_group_IDs!A:B,2,0) -> 203 | J40: Impact and Efficacy | K40: =VLOOKUP(J40,cardsort_subgroup_IDs!A:B,2,0) -> 321 | L40: =IF(E40="-",0,1)+IF(D40="-",0,2) -> 3 | M40: =IF(D40="-",0,LEN(D40)-LEN(SUBSTITUTE(D40,";",""))+1) -> 1 | N40: =IF(E40="-",0,LEN(E40)-LEN(SUBSTITUTE(E40,";",""))+1) -> 3 | O40: =SUM(M40:N40) -> 4 | P40: None | Q40: Organizational Effectiveness | R40: Complex | S40: -
...

Sheet urls
A1: ref_number | B1: ref_name | C1: company_size | D1: ref_link
A2: 5 | B2: D’Angelo et al. (2024) | C2: N/A | D2: https://doi.org/10.1109/MS.2024.3386027
A3: 6 | B3: Brown et al. (2023) | C3: N/A | D3: https://doi.org/10.1109/MS.2023.3305718
A4: 6a | B4: Google | C4: Enterprise | D4: https://doi.org/10.1109/MS.2023.3305718
A5: 7 | B5: Oliveira et al. (2020) | C5: N/A | D5: https://doi.org/10.1007/s10664-020-09820-z
A6: 9 | B6: Sanwal and Deva (2024) | C6: N/A | D6: https://www.ijtsrd.com/papers/ijtsrd69393.pdf
A7: 11 | B7: Gonçales et al. (2019) | C7: N/A | D7: https://doi.org/10.1109/ICPC.2019.00018
A8: 13 | B8: Edberg and Bowman (2015) | C8: N/A | D8: https://doi.org/10.1080/07421222.1996.11518117
A9: 14 | B9: Kokrehel and Bilicki (2021) | C9: N/A | D9: https://doi.org/10.1556/606.2021.00372
A10: 15 | B10: Oliveira et al. (2017) | C10: N/A | D10: https://doi.org/10.5220/0006314400760087
A11: 17 | B11: Green et al. (2024) | C11: N/A | D11: https://doi.org/10.1109/MS.2023.3324830
A12: 19 | B12: Meyer et al. (2014) | C12: N/A | D12: https://doi.org/10.1145/2635868.2635892
A13: 20 | B13: Green et al. (2023) | C13: N/A | D13: https://doi.org/10.1109/MS.2023.3291158
A14: 21 | B14: Treude et al. (2015) | C14: N/A | D14: https://doi.org/10.1145/2786805.2786827
A15: 31 | B15: Bao et al. (2022) | C15: N/A | D15: https://doi.org/10.1007/s11432-020-3278-4
A16: 32 | B16: Cheng et al. (2022) | C16: N/A | D16: https://doi.org/10.1145/3540250.3558940
... A70: 510 | B70: Slack | C70: Enterprise | D70: https://slack.engineering/mobile-developer-experience-at-slack/
A71: 131a | B71: Dropbox | C71: Large | D71: https://www.gitpod.io/blog/20-most-popular-developer-productivity-metrics
A72: 131b | B72: Netflix | C72: Enterprise | D72: https://www.gitpod.io/blog/20-most-popular-developer-productivity-metrics
A73: 131c | B73: Twitter/X | C73: Large | D73: https://www.gitpod.io/blog/20-most-popular-developer-productivity-metrics
A74: 131d | B74: Mozilla | C74: Mid-size | D74: https://www.gitpod.io/blog/20-most-popular-developer-productivity-metrics
A75: 131e | B75: Atlassian | C75: Enterprise | D75: https://www.gitpod.io/blog/20-most-popular-developer-productivity-metrics
A76: 131f | B76: SonarSource | C76: Mid-size | D76: https://www.gitpod.io/blog/20-most-popular-developer-productivity-metrics
A77: 131g | B77: Square | C77: Enterprise | D77: https://www.gitpod.io/blog/20-most-popular-developer-productivity-metrics
A78: 131h | B78: Etsy | C78: Large | D78: https://www.gitpod.io/blog/20-most-popular-developer-productivity-metrics
A79: 131i | B79: Stripe | C79: Enterprise | D79: https://www.gitpod.io/blog/20-most-popular-developer-productivity-metrics
A80: 131j | B80: Microsoft | C80: Enterprise | D80: https://www.gitpod.io/blog/20-most-popular-developer-productivity-metrics
A81: 131k | B81: Amazon | C81: Enterprise | D81: https://www.gitpod.io/blog/20-most-popular-developer-productivity-metrics
A82: 131l | B82: Meta | C82: Enterprise | D82: https://www.gitpod.io/blog/20-most-popular-developer-productivity-metrics
... A153: 523 | B153: Brandebusemeyer (2026) | C153: N/A | D153: https://dl.acm.org/doi/10.1145/3847122
A154: 524a | B154: SonarSource | C154: N/A | D154: https://www.sonarsource.com/resources/library/measuring-and-identifying-code-level-technical-debt-a-practical-guide/ | E154: Reference-for-Implementation
A155: 524b | B155: DX (2025) | C155: N/A | D155: https://getdx.com/blog/technical-debt-ratio/ | E155: Reference-for-Implementation
A156: 525a | B156: Storey (2026) | C156: N/A | D156: https://arxiv.org/abs/2603.22106
A157: 525b | B157: Alakmeh (2026) | C157: N/A | D157: https://dl.acm.org/doi/10.1145/3794763.3794804

Sheet cardsort_group_IDs
A1: Business | B1: 201
A2: System | B2: 202
A3: Developer Enablement | B3: 203
A4: Process | B4: 204
A5: Quality | B5: 205
A6: Team | B6: 206
A7: Output | B7: 207
A8: Customer | B8: 208

Sheet cardsort_subgroup_IDs
A1: Operational Flexibility | B1: 301
A2: Optimal Resource Allocation | B2: 302
A3: Build Time | B3: 303
A4: Reliability and Stability | B4: 304
A5: Focus Work | B5: 305
A6: Cycle Time | B6: 306
A7: Work Load | B7: 307
A8: Failure Rate | B8: 308
A9: Test Coverage | B9: 309
A10: Code Rework | B10: 310
A11: Review Process | B11: 311
A12: Produced Output | B12: 312
... A32: AI-Assisted Output | B32: 333

Sheet company_sizes
A1: company_size | B1: developer_count
A2: Enterprise | B2: 5000+ developers
A3: Large | B3: 501-5000
A4: Mid-size | B4: 51-500
A5: Small | B5: 1-50
A6: N/A | B6: research_instituation
